<robot name="robot_bugkuc">
  <link name="base">
    <visual>
      <origin xyz="0 0 0.5" rpy="0 0 0"/>
      <geometry>
        <box size="0.2 0.2 0.2"/>
      </geometry>
      <material name="blue">
        <color rgba="0.5 0.5 0.5 1"/>
      </material>
    </visual>
  </link>
  <joint name="joint_1" type="revolute">
    <parent link="base"/>
    <child link="link_1"/>
    <origin xyz="0.0 0.0 0.0" rpy="0.0 -0.0 0.0"/>
    <axis axis="0 0 1"/>
    <limit lower="-1.57" upper="1.57" effort="10" velocity="10"/>
  </joint>
  <link name="link_1">
    <visual>
      <origin xyz="0 0 -0.0" rpy="0 0 0"/>
      <geometry>
        <box size="0.1 0.1 0.2"/>
      </geometry>
      <material name="red">
        <color rgba="1 0.5 0 1"/>
      </material>
    </visual>
  </link>
  <joint name="joint_2" type="revolute">
    <parent link="link_1"/>
    <child link="link_2"/>
    <origin xyz="0.0 0.0 0.0" rpy="-0.7853980048633404 1.5696701507009851 0.7853980048633404"/>
    <axis axis="0 0 1"/>
    <limit lower="-1.57" upper="1.57" effort="10" velocity="10"/>
  </joint>
  <link name="link_2">
    <visual>
      <origin xyz="0 0 -0.0" rpy="0 0 0"/>
      <geometry>
        <box size="0.1 0.1 0.7"/>
      </geometry>
      <material name="green">
        <color rgba="1 0.5 0 1"/>
      </material>
    </visual>
  </link>
  <joint name="joint_3" type="revolute">
    <parent link="link_2"/>
    <child link="link_3"/>
    <origin xyz="0.8 0.0 0.0" rpy="0.0 -0.0 3.14"/>
    <axis axis="0 0 1"/>
    <limit lower="-1.57" upper="1.57" effort="10" velocity="10"/>
  </joint>
  <link name="link_3">
    <visual>
      <origin xyz="0 0 -0.4" rpy="0 0 0"/>
      <geometry>
        <box size="0.1 0.1 0.5"/>
      </geometry>
      <material name="red">
        <color rgba="1 0.5 0 1"/>
      </material>
    </visual>
  </link>
  <link name="tool">
    <visual>
      <origin xyz="0 0 0.005" rpy="0 0 0"/>
      <geometry>
        <box size="0.2 0.2 0.05"/>
      </geometry>
      <material name="blue">
        <color rgba="1 0.5 0 1"/>
      </material>
    </visual>
  </link>
</robot>
